<?xml version="1.0" ?>
<!-- =================================================================================== -->
<!-- |    This document was autogenerated by xacro from balltze.urdf.xacro             | -->
<!-- |    EDITING THIS FILE BY HAND IS NOT RECOMMENDED                                 | -->
<!-- =================================================================================== -->
<robot name="balltze">
  <link name="base_link"/>
  <link name="body_link">
    <visual>
      <geometry>
        <mesh filename="file:///ros2_ws/install/share/balltze_description/meshes/body_link.stl" scale="0.5 0.5 0.5"/>
      </geometry>
      <origin rpy="0.0 0.0 0.0" xyz="0.0 0.0 0.0"/>
    </visual>
    <collision>
      <geometry>
        <mesh filename="file:///ros2_ws/install/share/balltze_description/meshes/body_link_collision.stl" scale="0.5 0.5 0.5"/>
      </geometry>
      <origin rpy="0.0 0.0 0.0" xyz="0.0 0.0 0.0"/>
    </collision>
    <inertial>
      <mass value="1.0"/>
      <inertia ixx="0.1" ixy="0.0" ixz="0.0" iyy="0.1" iyz="0.0" izz="0.1"/>
    </inertial>
  </link>
  <link name="imu_link"/>
  <joint name="base_link_to_body_link_joint" type="fixed">
    <origin rpy="0.0 0.0 0.0" xyz="0.0 0.0 0.002"/>
    <parent link="base_link"/>
    <child link="body_link"/>
  </joint>
  <joint name="body_link_to_imu_link_joint" type="fixed">
    <origin rpy="0.0 0.0 0.0" xyz="0.0 0.0 0.01"/>
    <parent link="body_link"/>
    <child link="imu_link"/>
  </joint>
  <!-- LINK DEFINITION -->
  <link name="fl_link_1">
    <visual>
      <geometry>
        <sphere radius="0.02"/>
        <!-- <mesh filename="file://$(find balltze_description)/meshes/${side}_${link_name}.stl" scale="0.1 0.1 0.1" /> -->
      </geometry>
      <origin rpy="0.0 0.0 0.0" xyz="0.0 0.0 0.0"/>
    </visual>
    <collision>
      <geometry>
        <sphere radius="0.02"/>
        <!-- <mesh filename="file://$(find balltze_description)/meshes/${side}_${link_name}_collision.stl" scale="0.1 0.1 0.1" /> -->
      </geometry>
      <origin rpy="0.0 0.0 0.0" xyz="0.0 0.0 0.0"/>
    </collision>
    <inertial>
      <mass value="0.1"/>
      <inertia ixx="0.01" ixy="0" ixz="0" iyy="0.01" iyz="0" izz="0.01"/>
    </inertial>
  </link>
  <!-- LINK DEFINITION -->
  <link name="fl_link_2">
    <visual>
      <geometry>
        <sphere radius="0.02"/>
        <!-- <mesh filename="file://$(find balltze_description)/meshes/${side}_${link_name}.stl" scale="0.1 0.1 0.1" /> -->
      </geometry>
      <origin rpy="0.0 0.0 0.0" xyz="0.0 0.0 0.0"/>
    </visual>
    <collision>
      <geometry>
        <sphere radius="0.02"/>
        <!-- <mesh filename="file://$(find balltze_description)/meshes/${side}_${link_name}_collision.stl" scale="0.1 0.1 0.1" /> -->
      </geometry>
      <origin rpy="0.0 0.0 0.0" xyz="0.0 0.0 0.0"/>
    </collision>
    <inertial>
      <mass value="0.1"/>
      <inertia ixx="0.01" ixy="0" ixz="0" iyy="0.01" iyz="0" izz="0.01"/>
    </inertial>
  </link>
  <!-- LINK DEFINITION -->
  <link name="fl_link_3">
    <visual>
      <geometry>
        <sphere radius="0.02"/>
        <!-- <mesh filename="file://$(find balltze_description)/meshes/${side}_${link_name}.stl" scale="0.1 0.1 0.1" /> -->
      </geometry>
      <origin rpy="0.0 0.0 0.0" xyz="0.0 0.0 0.0"/>
    </visual>
    <collision>
      <geometry>
        <sphere radius="0.02"/>
        <!-- <mesh filename="file://$(find balltze_description)/meshes/${side}_${link_name}_collision.stl" scale="0.1 0.1 0.1" /> -->
      </geometry>
      <origin rpy="0.0 0.0 0.0" xyz="0.0 0.0 0.0"/>
    </collision>
    <inertial>
      <mass value="0.1"/>
      <inertia ixx="0.01" ixy="0" ixz="0" iyy="0.01" iyz="0" izz="0.01"/>
    </inertial>
  </link>
  <link name="fl_tip">
    <visual>
      <geometry>
        <sphere radius="0.02"/>
        <!-- <mesh filename="file://$(find balltze_description)/meshes/${side}_link_1.stl" scale="0.1 0.1 0.1" /> -->
      </geometry>
      <origin rpy="0.0 0.0 0.0" xyz="0.0 0.0 0.0"/>
    </visual>
    <collision name="fl_tip">
      <geometry>
        <sphere radius="0.02"/>
        <!-- <mesh filename="file://$(find balltze_description)/meshes/${side}_link_1_collision.stl" scale="0.1 0.1 0.1" /> -->
      </geometry>
      <origin rpy="0.0 0.0 0.0" xyz="0.0 0.0 0.0"/>
    </collision>
  </link>
  <!-- JOINT DEFINITION -->
  <joint name="fl_joint_1" type="revolute">
    <parent link="body_link"/>
    <child link="fl_link_1"/>
    <origin rpy="0.0 0.0 0.0" xyz="0.15 0.075 0.0"/>
    <axis xyz="1 0 0"/>
    <dynamics damping="0.0"/>
    <limit effort="1.5" lower="-0.7853981633974483" upper="0.7853981633974483" velocity="11.938052083641214"/>
  </joint>
  <!-- JOINT DEFINITION -->
  <joint name="fl_joint_2" type="revolute">
    <parent link="fl_link_1"/>
    <child link="fl_link_2"/>
    <origin rpy="0.0 0.0 0.0" xyz="0.0 0.06 0.0"/>
    <axis xyz="0 1 0"/>
    <dynamics damping="0.0"/>
    <limit effort="1.5" lower="-1.5707963267948966" upper="1.5707963267948966" velocity="11.938052083641214"/>
  </joint>
  <!-- JOINT DEFINITION -->
  <joint name="fl_joint_3" type="revolute">
    <parent link="fl_link_2"/>
    <child link="fl_link_3"/>
    <origin rpy="0.0 0.0 0.0" xyz="0.0 0.0 -0.11"/>
    <axis xyz="0 1 0"/>
    <dynamics damping="0.0"/>
    <limit effort="1.5" lower="-1.5707963267948966" upper="1.5707963267948966" velocity="11.938052083641214"/>
  </joint>
  <joint name="fl_joint_4" type="fixed">
    <parent link="fl_link_3"/>
    <child link="fl_tip"/>
    <origin rpy="0.0 0.0 0.0" xyz="0.15 0.0 0.0"/>
  </joint>
  <gazebo reference="fl_tip">
    <sensor name="fl_contact_system" type="contact">
      <contact>
        <topic>/balltze/fl_tip/contact</topic>
        <collision>fl_link_3_fixed_joint__fl_tip_collision_1</collision>
      </contact>
    </sensor>
  </gazebo>
  <!-- LINK DEFINITION -->
  <link name="fr_link_1">
    <visual>
      <geometry>
        <sphere radius="0.02"/>
        <!-- <mesh filename="file://$(find balltze_description)/meshes/${side}_${link_name}.stl" scale="0.1 0.1 0.1" /> -->
      </geometry>
      <origin rpy="0.0 0.0 0.0" xyz="0.0 0.0 0.0"/>
    </visual>
    <collision>
      <geometry>
        <sphere radius="0.02"/>
        <!-- <mesh filename="file://$(find balltze_description)/meshes/${side}_${link_name}_collision.stl" scale="0.1 0.1 0.1" /> -->
      </geometry>
      <origin rpy="0.0 0.0 0.0" xyz="0.0 0.0 0.0"/>
    </collision>
    <inertial>
      <mass value="0.1"/>
      <inertia ixx="0.01" ixy="0" ixz="0" iyy="0.01" iyz="0" izz="0.01"/>
    </inertial>
  </link>
  <!-- LINK DEFINITION -->
  <link name="fr_link_2">
    <visual>
      <geometry>
        <sphere radius="0.02"/>
        <!-- <mesh filename="file://$(find balltze_description)/meshes/${side}_${link_name}.stl" scale="0.1 0.1 0.1" /> -->
      </geometry>
      <origin rpy="0.0 0.0 0.0" xyz="0.0 0.0 0.0"/>
    </visual>
    <collision>
      <geometry>
        <sphere radius="0.02"/>
        <!-- <mesh filename="file://$(find balltze_description)/meshes/${side}_${link_name}_collision.stl" scale="0.1 0.1 0.1" /> -->
      </geometry>
      <origin rpy="0.0 0.0 0.0" xyz="0.0 0.0 0.0"/>
    </collision>
    <inertial>
      <mass value="0.1"/>
      <inertia ixx="0.01" ixy="0" ixz="0" iyy="0.01" iyz="0" izz="0.01"/>
    </inertial>
  </link>
  <!-- LINK DEFINITION -->
  <link name="fr_link_3">
    <visual>
      <geometry>
        <sphere radius="0.02"/>
        <!-- <mesh filename="file://$(find balltze_description)/meshes/${side}_${link_name}.stl" scale="0.1 0.1 0.1" /> -->
      </geometry>
      <origin rpy="0.0 0.0 0.0" xyz="0.0 0.0 0.0"/>
    </visual>
    <collision>
      <geometry>
        <sphere radius="0.02"/>
        <!-- <mesh filename="file://$(find balltze_description)/meshes/${side}_${link_name}_collision.stl" scale="0.1 0.1 0.1" /> -->
      </geometry>
      <origin rpy="0.0 0.0 0.0" xyz="0.0 0.0 0.0"/>
    </collision>
    <inertial>
      <mass value="0.1"/>
      <inertia ixx="0.01" ixy="0" ixz="0" iyy="0.01" iyz="0" izz="0.01"/>
    </inertial>
  </link>
  <link name="fr_tip">
    <visual>
      <geometry>
        <sphere radius="0.02"/>
        <!-- <mesh filename="file://$(find balltze_description)/meshes/${side}_link_1.stl" scale="0.1 0.1 0.1" /> -->
      </geometry>
      <origin rpy="0.0 0.0 0.0" xyz="0.0 0.0 0.0"/>
    </visual>
    <collision name="fr_tip">
      <geometry>
        <sphere radius="0.02"/>
        <!-- <mesh filename="file://$(find balltze_description)/meshes/${side}_link_1_collision.stl" scale="0.1 0.1 0.1" /> -->
      </geometry>
      <origin rpy="0.0 0.0 0.0" xyz="0.0 0.0 0.0"/>
    </collision>
  </link>
  <!-- JOINT DEFINITION -->
  <joint name="fr_joint_1" type="revolute">
    <parent link="body_link"/>
    <child link="fr_link_1"/>
    <origin rpy="0.0 0.0 0.0" xyz="0.15 -0.075 0.0"/>
    <axis xyz="1 0 0"/>
    <dynamics damping="0.0"/>
    <limit effort="1.5" lower="-0.7853981633974483" upper="0.7853981633974483" velocity="11.938052083641214"/>
  </joint>
  <!-- JOINT DEFINITION -->
  <joint name="fr_joint_2" type="revolute">
    <parent link="fr_link_1"/>
    <child link="fr_link_2"/>
    <origin rpy="0.0 0.0 0.0" xyz="0.0 -0.06 0.0"/>
    <axis xyz="0 1 0"/>
    <dynamics damping="0.0"/>
    <limit effort="1.5" lower="-1.5707963267948966" upper="1.5707963267948966" velocity="11.938052083641214"/>
  </joint>
  <!-- JOINT DEFINITION -->
  <joint name="fr_joint_3" type="revolute">
    <parent link="fr_link_2"/>
    <child link="fr_link_3"/>
    <origin rpy="0.0 0.0 0.0" xyz="0.0 -0.0 -0.11"/>
    <axis xyz="0 1 0"/>
    <dynamics damping="0.0"/>
    <limit effort="1.5" lower="-1.5707963267948966" upper="1.5707963267948966" velocity="11.938052083641214"/>
  </joint>
  <joint name="fr_joint_4" type="fixed">
    <parent link="fr_link_3"/>
    <child link="fr_tip"/>
    <origin rpy="0.0 0.0 0.0" xyz="0.15 -0.0 0.0"/>
  </joint>
  <gazebo reference="fr_tip">
    <sensor name="fr_contact_system" type="contact">
      <contact>
        <topic>/balltze/fr_tip/contact</topic>
        <collision>fr_link_3_fixed_joint__fr_tip_collision_1</collision>
      </contact>
    </sensor>
  </gazebo>
  <!-- LINK DEFINITION -->
  <link name="rl_link_1">
    <visual>
      <geometry>
        <sphere radius="0.02"/>
        <!-- <mesh filename="file://$(find balltze_description)/meshes/${side}_${link_name}.stl" scale="0.1 0.1 0.1" /> -->
      </geometry>
      <origin rpy="0.0 0.0 0.0" xyz="0.0 0.0 0.0"/>
    </visual>
    <collision>
      <geometry>
        <sphere radius="0.02"/>
        <!-- <mesh filename="file://$(find balltze_description)/meshes/${side}_${link_name}_collision.stl" scale="0.1 0.1 0.1" /> -->
      </geometry>
      <origin rpy="0.0 0.0 0.0" xyz="0.0 0.0 0.0"/>
    </collision>
    <inertial>
      <mass value="0.1"/>
      <inertia ixx="0.01" ixy="0" ixz="0" iyy="0.01" iyz="0" izz="0.01"/>
    </inertial>
  </link>
  <!-- LINK DEFINITION -->
  <link name="rl_link_2">
    <visual>
      <geometry>
        <sphere radius="0.02"/>
        <!-- <mesh filename="file://$(find balltze_description)/meshes/${side}_${link_name}.stl" scale="0.1 0.1 0.1" /> -->
      </geometry>
      <origin rpy="0.0 0.0 0.0" xyz="0.0 0.0 0.0"/>
    </visual>
    <collision>
      <geometry>
        <sphere radius="0.02"/>
        <!-- <mesh filename="file://$(find balltze_description)/meshes/${side}_${link_name}_collision.stl" scale="0.1 0.1 0.1" /> -->
      </geometry>
      <origin rpy="0.0 0.0 0.0" xyz="0.0 0.0 0.0"/>
    </collision>
    <inertial>
      <mass value="0.1"/>
      <inertia ixx="0.01" ixy="0" ixz="0" iyy="0.01" iyz="0" izz="0.01"/>
    </inertial>
  </link>
  <!-- LINK DEFINITION -->
  <link name="rl_link_3">
    <visual>
      <geometry>
        <sphere radius="0.02"/>
        <!-- <mesh filename="file://$(find balltze_description)/meshes/${side}_${link_name}.stl" scale="0.1 0.1 0.1" /> -->
      </geometry>
      <origin rpy="0.0 0.0 0.0" xyz="0.0 0.0 0.0"/>
    </visual>
    <collision>
      <geometry>
        <sphere radius="0.02"/>
        <!-- <mesh filename="file://$(find balltze_description)/meshes/${side}_${link_name}_collision.stl" scale="0.1 0.1 0.1" /> -->
      </geometry>
      <origin rpy="0.0 0.0 0.0" xyz="0.0 0.0 0.0"/>
    </collision>
    <inertial>
      <mass value="0.1"/>
      <inertia ixx="0.01" ixy="0" ixz="0" iyy="0.01" iyz="0" izz="0.01"/>
    </inertial>
  </link>
  <link name="rl_tip">
    <visual>
      <geometry>
        <sphere radius="0.02"/>
        <!-- <mesh filename="file://$(find balltze_description)/meshes/${side}_link_1.stl" scale="0.1 0.1 0.1" /> -->
      </geometry>
      <origin rpy="0.0 0.0 0.0" xyz="0.0 0.0 0.0"/>
    </visual>
    <collision name="rl_tip">
      <geometry>
        <sphere radius="0.02"/>
        <!-- <mesh filename="file://$(find balltze_description)/meshes/${side}_link_1_collision.stl" scale="0.1 0.1 0.1" /> -->
      </geometry>
      <origin rpy="0.0 0.0 0.0" xyz="0.0 0.0 0.0"/>
    </collision>
  </link>
  <!-- JOINT DEFINITION -->
  <joint name="rl_joint_1" type="revolute">
    <parent link="body_link"/>
    <child link="rl_link_1"/>
    <origin rpy="0.0 0.0 0.0" xyz="-0.15 0.075 0.0"/>
    <axis xyz="1 0 0"/>
    <dynamics damping="0.0"/>
    <limit effort="1.5" lower="-0.7853981633974483" upper="0.7853981633974483" velocity="11.938052083641214"/>
  </joint>
  <!-- JOINT DEFINITION -->
  <joint name="rl_joint_2" type="revolute">
    <parent link="rl_link_1"/>
    <child link="rl_link_2"/>
    <origin rpy="0.0 0.0 0.0" xyz="0.0 0.06 0.0"/>
    <axis xyz="0 1 0"/>
    <dynamics damping="0.0"/>
    <limit effort="1.5" lower="-1.5707963267948966" upper="1.5707963267948966" velocity="11.938052083641214"/>
  </joint>
  <!-- JOINT DEFINITION -->
  <joint name="rl_joint_3" type="revolute">
    <parent link="rl_link_2"/>
    <child link="rl_link_3"/>
    <origin rpy="0.0 0.0 0.0" xyz="0.0 0.0 -0.11"/>
    <axis xyz="0 1 0"/>
    <dynamics damping="0.0"/>
    <limit effort="1.5" lower="-1.5707963267948966" upper="1.5707963267948966" velocity="11.938052083641214"/>
  </joint>
  <joint name="rl_joint_4" type="fixed">
    <parent link="rl_link_3"/>
    <child link="rl_tip"/>
    <origin rpy="0.0 0.0 0.0" xyz="0.15 0.0 0.0"/>
  </joint>
  <gazebo reference="rl_tip">
    <sensor name="rl_contact_system" type="contact">
      <contact>
        <topic>/balltze/rl_tip/contact</topic>
        <collision>rl_link_3_fixed_joint__rl_tip_collision_1</collision>
      </contact>
    </sensor>
  </gazebo>
  <!-- LINK DEFINITION -->
  <link name="rr_link_1">
    <visual>
      <geometry>
        <sphere radius="0.02"/>
        <!-- <mesh filename="file://$(find balltze_description)/meshes/${side}_${link_name}.stl" scale="0.1 0.1 0.1" /> -->
      </geometry>
      <origin rpy="0.0 0.0 0.0" xyz="0.0 0.0 0.0"/>
    </visual>
    <collision>
      <geometry>
        <sphere radius="0.02"/>
        <!-- <mesh filename="file://$(find balltze_description)/meshes/${side}_${link_name}_collision.stl" scale="0.1 0.1 0.1" /> -->
      </geometry>
      <origin rpy="0.0 0.0 0.0" xyz="0.0 0.0 0.0"/>
    </collision>
    <inertial>
      <mass value="0.1"/>
      <inertia ixx="0.01" ixy="0" ixz="0" iyy="0.01" iyz="0" izz="0.01"/>
    </inertial>
  </link>
  <!-- LINK DEFINITION -->
  <link name="rr_link_2">
    <visual>
      <geometry>
        <sphere radius="0.02"/>
        <!-- <mesh filename="file://$(find balltze_description)/meshes/${side}_${link_name}.stl" scale="0.1 0.1 0.1" /> -->
      </geometry>
      <origin rpy="0.0 0.0 0.0" xyz="0.0 0.0 0.0"/>
    </visual>
    <collision>
      <geometry>
        <sphere radius="0.02"/>
        <!-- <mesh filename="file://$(find balltze_description)/meshes/${side}_${link_name}_collision.stl" scale="0.1 0.1 0.1" /> -->
      </geometry>
      <origin rpy="0.0 0.0 0.0" xyz="0.0 0.0 0.0"/>
    </collision>
    <inertial>
      <mass value="0.1"/>
      <inertia ixx="0.01" ixy="0" ixz="0" iyy="0.01" iyz="0" izz="0.01"/>
    </inertial>
  </link>
  <!-- LINK DEFINITION -->
  <link name="rr_link_3">
    <visual>
      <geometry>
        <sphere radius="0.02"/>
        <!-- <mesh filename="file://$(find balltze_description)/meshes/${side}_${link_name}.stl" scale="0.1 0.1 0.1" /> -->
      </geometry>
      <origin rpy="0.0 0.0 0.0" xyz="0.0 0.0 0.0"/>
    </visual>
    <collision>
      <geometry>
        <sphere radius="0.02"/>
        <!-- <mesh filename="file://$(find balltze_description)/meshes/${side}_${link_name}_collision.stl" scale="0.1 0.1 0.1" /> -->
      </geometry>
      <origin rpy="0.0 0.0 0.0" xyz="0.0 0.0 0.0"/>
    </collision>
    <inertial>
      <mass value="0.1"/>
      <inertia ixx="0.01" ixy="0" ixz="0" iyy="0.01" iyz="0" izz="0.01"/>
    </inertial>
  </link>
  <link name="rr_tip">
    <visual>
      <geometry>
        <sphere radius="0.02"/>
        <!-- <mesh filename="file://$(find balltze_description)/meshes/${side}_link_1.stl" scale="0.1 0.1 0.1" /> -->
      </geometry>
      <origin rpy="0.0 0.0 0.0" xyz="0.0 0.0 0.0"/>
    </visual>
    <collision name="rr_tip">
      <geometry>
        <sphere radius="0.02"/>
        <!-- <mesh filename="file://$(find balltze_description)/meshes/${side}_link_1_collision.stl" scale="0.1 0.1 0.1" /> -->
      </geometry>
      <origin rpy="0.0 0.0 0.0" xyz="0.0 0.0 0.0"/>
    </collision>
  </link>
  <!-- JOINT DEFINITION -->
  <joint name="rr_joint_1" type="revolute">
    <parent link="body_link"/>
    <child link="rr_link_1"/>
    <origin rpy="0.0 0.0 0.0" xyz="-0.15 -0.075 0.0"/>
    <axis xyz="1 0 0"/>
    <dynamics damping="0.0"/>
    <limit effort="1.5" lower="-0.7853981633974483" upper="0.7853981633974483" velocity="11.938052083641214"/>
  </joint>
  <!-- JOINT DEFINITION -->
  <joint name="rr_joint_2" type="revolute">
    <parent link="rr_link_1"/>
    <child link="rr_link_2"/>
    <origin rpy="0.0 0.0 0.0" xyz="0.0 -0.06 0.0"/>
    <axis xyz="0 1 0"/>
    <dynamics damping="0.0"/>
    <limit effort="1.5" lower="-1.5707963267948966" upper="1.5707963267948966" velocity="11.938052083641214"/>
  </joint>
  <!-- JOINT DEFINITION -->
  <joint name="rr_joint_3" type="revolute">
    <parent link="rr_link_2"/>
    <child link="rr_link_3"/>
    <origin rpy="0.0 0.0 0.0" xyz="0.0 -0.0 -0.11"/>
    <axis xyz="0 1 0"/>
    <dynamics damping="0.0"/>
    <limit effort="1.5" lower="-1.5707963267948966" upper="1.5707963267948966" velocity="11.938052083641214"/>
  </joint>
  <joint name="rr_joint_4" type="fixed">
    <parent link="rr_link_3"/>
    <child link="rr_tip"/>
    <origin rpy="0.0 0.0 0.0" xyz="0.15 -0.0 0.0"/>
  </joint>
  <gazebo reference="rr_tip">
    <sensor name="rr_contact_system" type="contact">
      <contact>
        <topic>/balltze/rr_tip/contact</topic>
        <collision>rr_link_3_fixed_joint__rr_tip_collision_1</collision>
      </contact>
    </sensor>
  </gazebo>
  <ros2_control name="DynamixelSystemf" type="system">
    <hardware>
      <plugin>balltze_dynamixel_system/BalltzeDynamixelSystem</plugin>
      <param name="serial_port">/dev/ttyUSB1</param>
      <param name="baudrate">1000000</param>
      <param name="return_delay">50</param>
    </hardware>
    <joint name="fl_joint_1">
      <command_interface name="position"/>
      <command_interface name="velocity"/>
      <!-- <command_interface name="effort" /> -->
      <state_interface name="position"/>
      <state_interface name="velocity"/>
      <state_interface name="effort"/>
      <param name="id">1</param>
      <param name="inverted">True</param>
    </joint>
    <joint name="fl_joint_2">
      <command_interface name="position"/>
      <command_interface name="velocity"/>
      <!-- <command_interface name="effort" /> -->
      <state_interface name="position"/>
      <state_interface name="velocity"/>
      <state_interface name="effort"/>
      <param name="id">2</param>
      <param name="inverted">True</param>
    </joint>
    <joint name="fl_joint_3">
      <command_interface name="position"/>
      <command_interface name="velocity"/>
      <!-- <command_interface name="effort" /> -->
      <state_interface name="position"/>
      <state_interface name="velocity"/>
      <state_interface name="effort"/>
      <param name="id">3</param>
      <param name="inverted">False</param>
    </joint>
    <joint name="fr_joint_1">
      <command_interface name="position"/>
      <command_interface name="velocity"/>
      <!-- <command_interface name="effort" /> -->
      <state_interface name="position"/>
      <state_interface name="velocity"/>
      <state_interface name="effort"/>
      <param name="id">4</param>
      <param name="inverted">True</param>
    </joint>
    <joint name="fr_joint_2">
      <command_interface name="position"/>
      <command_interface name="velocity"/>
      <!-- <command_interface name="effort" /> -->
      <state_interface name="position"/>
      <state_interface name="velocity"/>
      <state_interface name="effort"/>
      <param name="id">5</param>
      <param name="inverted">False</param>
    </joint>
    <joint name="fr_joint_3">
      <command_interface name="position"/>
      <command_interface name="velocity"/>
      <!-- <command_interface name="effort" /> -->
      <state_interface name="position"/>
      <state_interface name="velocity"/>
      <state_interface name="effort"/>
      <param name="id">6</param>
      <param name="inverted">True</param>
    </joint>
  </ros2_control>
  <ros2_control name="DynamixelSystemr" type="system">
    <hardware>
      <plugin>balltze_dynamixel_system/BalltzeDynamixelSystem</plugin>
      <param name="serial_port">/dev/ttyUSB3</param>
      <param name="baudrate">1000000</param>
      <param name="return_delay">50</param>
    </hardware>
    <joint name="rl_joint_1">
      <command_interface name="position"/>
      <command_interface name="velocity"/>
      <!-- <command_interface name="effort" /> -->
      <state_interface name="position"/>
      <state_interface name="velocity"/>
      <state_interface name="effort"/>
      <param name="id">1</param>
      <param name="inverted">False</param>
    </joint>
    <joint name="rl_joint_2">
      <command_interface name="position"/>
      <command_interface name="velocity"/>
      <!-- <command_interface name="effort" /> -->
      <state_interface name="position"/>
      <state_interface name="velocity"/>
      <state_interface name="effort"/>
      <param name="id">2</param>
      <param name="inverted">True</param>
    </joint>
    <joint name="rl_joint_3">
      <command_interface name="position"/>
      <command_interface name="velocity"/>
      <!-- <command_interface name="effort" /> -->
      <state_interface name="position"/>
      <state_interface name="velocity"/>
      <state_interface name="effort"/>
      <param name="id">3</param>
      <param name="inverted">False</param>
    </joint>
    <joint name="rr_joint_1">
      <command_interface name="position"/>
      <command_interface name="velocity"/>
      <!-- <command_interface name="effort" /> -->
      <state_interface name="position"/>
      <state_interface name="velocity"/>
      <state_interface name="effort"/>
      <param name="id">4</param>
      <param name="inverted">False</param>
    </joint>
    <joint name="rr_joint_2">
      <command_interface name="position"/>
      <command_interface name="velocity"/>
      <!-- <command_interface name="effort" /> -->
      <state_interface name="position"/>
      <state_interface name="velocity"/>
      <state_interface name="effort"/>
      <param name="id">5</param>
      <param name="inverted">False</param>
    </joint>
    <joint name="rr_joint_3">
      <command_interface name="position"/>
      <command_interface name="velocity"/>
      <!-- <command_interface name="effort" /> -->
      <state_interface name="position"/>
      <state_interface name="velocity"/>
      <state_interface name="effort"/>
      <param name="id">6</param>
      <param name="inverted">True</param>
    </joint>
  </ros2_control>
</robot>
