<?xml version="1.0" ?>
<!-- =================================================================================== -->
<!-- |    This document was autogenerated by xacro from balltze.urdf.xacro             | -->
<!-- |    EDITING THIS FILE BY HAND IS NOT RECOMMENDED                                 | -->
<!-- =================================================================================== -->
<robot name="balltze">
  <link name="base_link"/>
  <link name="body_link">
    <visual>
      <geometry>
        <mesh filename="file:///ros2_ws/install/share/balltze_description/meshes/body_link.stl" scale="0.5 0.5 0.5"/>
      </geometry>
      <origin rpy="0.0 0.0 0.0" xyz="0.0 0.0 0.0"/>
    </visual>
    <collision>
      <geometry>
        <mesh filename="file:///ros2_ws/install/share/balltze_description/meshes/body_link_collision.stl" scale="0.5 0.5 0.5"/>
      </geometry>
      <origin rpy="0.0 0.0 0.0" xyz="0.0 0.0 0.0"/>
    </collision>
    <inertial>
      <mass value="1.2"/>
      <inertia ixx="1.0" ixy="0.0" ixz="0.0" iyy="1.0" iyz="0.0" izz="1.0"/>
    </inertial>
  </link>
  <link name="imu_link"/>
  <joint name="base_link_to_body_link_joint" type="fixed">
    <origin rpy="0.0 0.0 0.0" xyz="0.0 0.0 0.0"/>
    <parent link="base_link"/>
    <child link="body_link"/>
  </joint>
  <joint name="body_link_to_imu_link_joint" type="fixed">
    <origin rpy="0.0 0.0 0.0" xyz="0.0 0.0 0.0"/>
    <parent link="body_link"/>
    <child link="imu_link"/>
  </joint>
  <!-- LINK DEFINITION -->
  <link name="front_left_coxa_link">
    <visual>
      <geometry>
        <mesh filename="file:///ros2_ws/install/share/balltze_description/meshes/left_coxa_link.stl" scale="0.1 0.1 0.1"/>
      </geometry>
      <origin rpy="0.0 0.0 0.0" xyz="0.0 0.0 0.0"/>
    </visual>
    <collision>
      <geometry>
        <mesh filename="file:///ros2_ws/install/share/balltze_description/meshes/left_coxa_link_collision.stl" scale="0.1 0.1 0.1"/>
      </geometry>
      <origin rpy="0.0 0.0 0.0" xyz="0.0 0.0 0.0"/>
    </collision>
    <inertial>
      <mass value="0.00000000001"/>
      <inertia ixx="1" ixy="0" ixz="0" iyy="1" iyz="0" izz="1"/>
    </inertial>
  </link>
  <!-- LINK DEFINITION -->
  <link name="front_left_femur_link">
    <visual>
      <geometry>
        <mesh filename="file:///ros2_ws/install/share/balltze_description/meshes/left_femur_link.stl" scale="0.1 0.1 0.1"/>
      </geometry>
      <origin rpy="0.0 0.0 0.0" xyz="0.0 0.0 0.0"/>
    </visual>
    <collision>
      <geometry>
        <mesh filename="file:///ros2_ws/install/share/balltze_description/meshes/left_femur_link_collision.stl" scale="0.1 0.1 0.1"/>
      </geometry>
      <origin rpy="0.0 0.0 0.0" xyz="0.0 0.0 0.0"/>
    </collision>
    <inertial>
      <mass value="0.00000000001"/>
      <inertia ixx="1" ixy="0" ixz="0" iyy="1" iyz="0" izz="1"/>
    </inertial>
  </link>
  <!-- LINK DEFINITION -->
  <link name="front_left_tibia_link">
    <visual>
      <geometry>
        <mesh filename="file:///ros2_ws/install/share/balltze_description/meshes/left_tibia_link.stl" scale="0.1 0.1 0.1"/>
      </geometry>
      <origin rpy="0.0 0.0 0.0" xyz="0.0 0.0 0.0"/>
    </visual>
    <collision>
      <geometry>
        <mesh filename="file:///ros2_ws/install/share/balltze_description/meshes/left_tibia_link_collision.stl" scale="0.1 0.1 0.1"/>
      </geometry>
      <origin rpy="0.0 0.0 0.0" xyz="0.0 0.0 0.0"/>
    </collision>
    <inertial>
      <mass value="0.00000000001"/>
      <inertia ixx="1" ixy="0" ixz="0" iyy="1" iyz="0" izz="1"/>
    </inertial>
  </link>
  <link name="front_left_tip_link">
    <visual>
      <geometry>
        <mesh filename="file:///ros2_ws/install/share/balltze_description/meshes/left_coxa_link.stl" scale="0.1 0.1 0.1"/>
      </geometry>
      <origin rpy="0.0 0.0 0.0" xyz="0.0 0.0 0.0"/>
    </visual>
    <collision>
      <geometry>
        <mesh filename="file:///ros2_ws/install/share/balltze_description/meshes/left_coxa_link_collision.stl" scale="0.1 0.1 0.1"/>
      </geometry>
      <origin rpy="0.0 0.0 0.0" xyz="0.0 0.0 0.0"/>
    </collision>
  </link>
  <!-- JOINT DEFINITION -->
  <joint name="front_left_body_link_to_body_link_joint" type="revolute">
    <parent link="body_link"/>
    <child link="front_left_coxa_link"/>
    <origin rpy="0.0 0.0 0.0" xyz="0.15 0.075 0.0"/>
    <axis xyz="1 0 0"/>
    <limit effort="1.5" lower="2.6179938779914944" upper="-2.6179938779914944" velocity="11.938052083641214"/>
  </joint>
  <!-- JOINT DEFINITION -->
  <joint name="front_left_coxa_link_to_coxa_link_joint" type="revolute">
    <parent link="front_left_coxa_link"/>
    <child link="front_left_femur_link"/>
    <origin rpy="0.0 0.0 0.0" xyz="0.0 0.06 0.0"/>
    <axis xyz="0 1 0"/>
    <limit effort="1.5" lower="2.6179938779914944" upper="-2.6179938779914944" velocity="11.938052083641214"/>
  </joint>
  <!-- JOINT DEFINITION -->
  <joint name="front_left_femur_link_to_femur_link_joint" type="revolute">
    <parent link="front_left_femur_link"/>
    <child link="front_left_tibia_link"/>
    <origin rpy="0.0 0.0 0.0" xyz="0.0 0.0 -0.11"/>
    <axis xyz="0 1 0"/>
    <limit effort="1.5" lower="2.6179938779914944" upper="-2.6179938779914944" velocity="11.938052083641214"/>
  </joint>
  <joint name="front_left_tibia_link_to_tip_link_joint" type="fixed">
    <parent link="front_left_tibia_link"/>
    <child link="front_left_tip_link"/>
    <origin rpy="0.0 0.0 0.0" xyz="0.15 0.0 0.0"/>
  </joint>
  <!-- LINK DEFINITION -->
  <link name="front_right_coxa_link">
    <visual>
      <geometry>
        <mesh filename="file:///ros2_ws/install/share/balltze_description/meshes/left_coxa_link.stl" scale="0.1 0.1 0.1"/>
      </geometry>
      <origin rpy="0.0 0.0 0.0" xyz="0.0 0.0 0.0"/>
    </visual>
    <collision>
      <geometry>
        <mesh filename="file:///ros2_ws/install/share/balltze_description/meshes/left_coxa_link_collision.stl" scale="0.1 0.1 0.1"/>
      </geometry>
      <origin rpy="0.0 0.0 0.0" xyz="0.0 0.0 0.0"/>
    </collision>
    <inertial>
      <mass value="0.00000000001"/>
      <inertia ixx="1" ixy="0" ixz="0" iyy="1" iyz="0" izz="1"/>
    </inertial>
  </link>
  <!-- LINK DEFINITION -->
  <link name="front_right_femur_link">
    <visual>
      <geometry>
        <mesh filename="file:///ros2_ws/install/share/balltze_description/meshes/left_femur_link.stl" scale="0.1 0.1 0.1"/>
      </geometry>
      <origin rpy="0.0 0.0 0.0" xyz="0.0 0.0 0.0"/>
    </visual>
    <collision>
      <geometry>
        <mesh filename="file:///ros2_ws/install/share/balltze_description/meshes/left_femur_link_collision.stl" scale="0.1 0.1 0.1"/>
      </geometry>
      <origin rpy="0.0 0.0 0.0" xyz="0.0 0.0 0.0"/>
    </collision>
    <inertial>
      <mass value="0.00000000001"/>
      <inertia ixx="1" ixy="0" ixz="0" iyy="1" iyz="0" izz="1"/>
    </inertial>
  </link>
  <!-- LINK DEFINITION -->
  <link name="front_right_tibia_link">
    <visual>
      <geometry>
        <mesh filename="file:///ros2_ws/install/share/balltze_description/meshes/left_tibia_link.stl" scale="0.1 0.1 0.1"/>
      </geometry>
      <origin rpy="0.0 0.0 0.0" xyz="0.0 0.0 0.0"/>
    </visual>
    <collision>
      <geometry>
        <mesh filename="file:///ros2_ws/install/share/balltze_description/meshes/left_tibia_link_collision.stl" scale="0.1 0.1 0.1"/>
      </geometry>
      <origin rpy="0.0 0.0 0.0" xyz="0.0 0.0 0.0"/>
    </collision>
    <inertial>
      <mass value="0.00000000001"/>
      <inertia ixx="1" ixy="0" ixz="0" iyy="1" iyz="0" izz="1"/>
    </inertial>
  </link>
  <link name="front_right_tip_link">
    <visual>
      <geometry>
        <mesh filename="file:///ros2_ws/install/share/balltze_description/meshes/left_coxa_link.stl" scale="0.1 0.1 0.1"/>
      </geometry>
      <origin rpy="0.0 0.0 0.0" xyz="0.0 0.0 0.0"/>
    </visual>
    <collision>
      <geometry>
        <mesh filename="file:///ros2_ws/install/share/balltze_description/meshes/left_coxa_link_collision.stl" scale="0.1 0.1 0.1"/>
      </geometry>
      <origin rpy="0.0 0.0 0.0" xyz="0.0 0.0 0.0"/>
    </collision>
  </link>
  <!-- JOINT DEFINITION -->
  <joint name="front_right_body_link_to_body_link_joint" type="revolute">
    <parent link="body_link"/>
    <child link="front_right_coxa_link"/>
    <origin rpy="0.0 0.0 0.0" xyz="0.15 -0.075 0.0"/>
    <axis xyz="1 0 0"/>
    <limit effort="1.5" lower="2.6179938779914944" upper="-2.6179938779914944" velocity="11.938052083641214"/>
  </joint>
  <!-- JOINT DEFINITION -->
  <joint name="front_right_coxa_link_to_coxa_link_joint" type="revolute">
    <parent link="front_right_coxa_link"/>
    <child link="front_right_femur_link"/>
    <origin rpy="0.0 0.0 0.0" xyz="0.0 -0.06 0.0"/>
    <axis xyz="0 1 0"/>
    <limit effort="1.5" lower="2.6179938779914944" upper="-2.6179938779914944" velocity="11.938052083641214"/>
  </joint>
  <!-- JOINT DEFINITION -->
  <joint name="front_right_femur_link_to_femur_link_joint" type="revolute">
    <parent link="front_right_femur_link"/>
    <child link="front_right_tibia_link"/>
    <origin rpy="0.0 0.0 0.0" xyz="0.0 -0.0 -0.11"/>
    <axis xyz="0 1 0"/>
    <limit effort="1.5" lower="2.6179938779914944" upper="-2.6179938779914944" velocity="11.938052083641214"/>
  </joint>
  <joint name="front_right_tibia_link_to_tip_link_joint" type="fixed">
    <parent link="front_right_tibia_link"/>
    <child link="front_right_tip_link"/>
    <origin rpy="0.0 0.0 0.0" xyz="0.15 -0.0 0.0"/>
  </joint>
  <!-- LINK DEFINITION -->
  <link name="rear_left_coxa_link">
    <visual>
      <geometry>
        <mesh filename="file:///ros2_ws/install/share/balltze_description/meshes/left_coxa_link.stl" scale="0.1 0.1 0.1"/>
      </geometry>
      <origin rpy="0.0 0.0 0.0" xyz="0.0 0.0 0.0"/>
    </visual>
    <collision>
      <geometry>
        <mesh filename="file:///ros2_ws/install/share/balltze_description/meshes/left_coxa_link_collision.stl" scale="0.1 0.1 0.1"/>
      </geometry>
      <origin rpy="0.0 0.0 0.0" xyz="0.0 0.0 0.0"/>
    </collision>
    <inertial>
      <mass value="0.00000000001"/>
      <inertia ixx="1" ixy="0" ixz="0" iyy="1" iyz="0" izz="1"/>
    </inertial>
  </link>
  <!-- LINK DEFINITION -->
  <link name="rear_left_femur_link">
    <visual>
      <geometry>
        <mesh filename="file:///ros2_ws/install/share/balltze_description/meshes/left_femur_link.stl" scale="0.1 0.1 0.1"/>
      </geometry>
      <origin rpy="0.0 0.0 0.0" xyz="0.0 0.0 0.0"/>
    </visual>
    <collision>
      <geometry>
        <mesh filename="file:///ros2_ws/install/share/balltze_description/meshes/left_femur_link_collision.stl" scale="0.1 0.1 0.1"/>
      </geometry>
      <origin rpy="0.0 0.0 0.0" xyz="0.0 0.0 0.0"/>
    </collision>
    <inertial>
      <mass value="0.00000000001"/>
      <inertia ixx="1" ixy="0" ixz="0" iyy="1" iyz="0" izz="1"/>
    </inertial>
  </link>
  <!-- LINK DEFINITION -->
  <link name="rear_left_tibia_link">
    <visual>
      <geometry>
        <mesh filename="file:///ros2_ws/install/share/balltze_description/meshes/left_tibia_link.stl" scale="0.1 0.1 0.1"/>
      </geometry>
      <origin rpy="0.0 0.0 0.0" xyz="0.0 0.0 0.0"/>
    </visual>
    <collision>
      <geometry>
        <mesh filename="file:///ros2_ws/install/share/balltze_description/meshes/left_tibia_link_collision.stl" scale="0.1 0.1 0.1"/>
      </geometry>
      <origin rpy="0.0 0.0 0.0" xyz="0.0 0.0 0.0"/>
    </collision>
    <inertial>
      <mass value="0.00000000001"/>
      <inertia ixx="1" ixy="0" ixz="0" iyy="1" iyz="0" izz="1"/>
    </inertial>
  </link>
  <link name="rear_left_tip_link">
    <visual>
      <geometry>
        <mesh filename="file:///ros2_ws/install/share/balltze_description/meshes/left_coxa_link.stl" scale="0.1 0.1 0.1"/>
      </geometry>
      <origin rpy="0.0 0.0 0.0" xyz="0.0 0.0 0.0"/>
    </visual>
    <collision>
      <geometry>
        <mesh filename="file:///ros2_ws/install/share/balltze_description/meshes/left_coxa_link_collision.stl" scale="0.1 0.1 0.1"/>
      </geometry>
      <origin rpy="0.0 0.0 0.0" xyz="0.0 0.0 0.0"/>
    </collision>
  </link>
  <!-- JOINT DEFINITION -->
  <joint name="rear_left_body_link_to_body_link_joint" type="revolute">
    <parent link="body_link"/>
    <child link="rear_left_coxa_link"/>
    <origin rpy="0.0 0.0 0.0" xyz="-0.15 0.075 0.0"/>
    <axis xyz="1 0 0"/>
    <limit effort="1.5" lower="2.6179938779914944" upper="-2.6179938779914944" velocity="11.938052083641214"/>
  </joint>
  <!-- JOINT DEFINITION -->
  <joint name="rear_left_coxa_link_to_coxa_link_joint" type="revolute">
    <parent link="rear_left_coxa_link"/>
    <child link="rear_left_femur_link"/>
    <origin rpy="0.0 0.0 0.0" xyz="0.0 0.06 0.0"/>
    <axis xyz="0 1 0"/>
    <limit effort="1.5" lower="2.6179938779914944" upper="-2.6179938779914944" velocity="11.938052083641214"/>
  </joint>
  <!-- JOINT DEFINITION -->
  <joint name="rear_left_femur_link_to_femur_link_joint" type="revolute">
    <parent link="rear_left_femur_link"/>
    <child link="rear_left_tibia_link"/>
    <origin rpy="0.0 0.0 0.0" xyz="0.0 0.0 -0.11"/>
    <axis xyz="0 1 0"/>
    <limit effort="1.5" lower="2.6179938779914944" upper="-2.6179938779914944" velocity="11.938052083641214"/>
  </joint>
  <joint name="rear_left_tibia_link_to_tip_link_joint" type="fixed">
    <parent link="rear_left_tibia_link"/>
    <child link="rear_left_tip_link"/>
    <origin rpy="0.0 0.0 0.0" xyz="0.15 0.0 0.0"/>
  </joint>
  <!-- LINK DEFINITION -->
  <link name="rear_right_coxa_link">
    <visual>
      <geometry>
        <mesh filename="file:///ros2_ws/install/share/balltze_description/meshes/left_coxa_link.stl" scale="0.1 0.1 0.1"/>
      </geometry>
      <origin rpy="0.0 0.0 0.0" xyz="0.0 0.0 0.0"/>
    </visual>
    <collision>
      <geometry>
        <mesh filename="file:///ros2_ws/install/share/balltze_description/meshes/left_coxa_link_collision.stl" scale="0.1 0.1 0.1"/>
      </geometry>
      <origin rpy="0.0 0.0 0.0" xyz="0.0 0.0 0.0"/>
    </collision>
    <inertial>
      <mass value="0.00000000001"/>
      <inertia ixx="1" ixy="0" ixz="0" iyy="1" iyz="0" izz="1"/>
    </inertial>
  </link>
  <!-- LINK DEFINITION -->
  <link name="rear_right_femur_link">
    <visual>
      <geometry>
        <mesh filename="file:///ros2_ws/install/share/balltze_description/meshes/left_femur_link.stl" scale="0.1 0.1 0.1"/>
      </geometry>
      <origin rpy="0.0 0.0 0.0" xyz="0.0 0.0 0.0"/>
    </visual>
    <collision>
      <geometry>
        <mesh filename="file:///ros2_ws/install/share/balltze_description/meshes/left_femur_link_collision.stl" scale="0.1 0.1 0.1"/>
      </geometry>
      <origin rpy="0.0 0.0 0.0" xyz="0.0 0.0 0.0"/>
    </collision>
    <inertial>
      <mass value="0.00000000001"/>
      <inertia ixx="1" ixy="0" ixz="0" iyy="1" iyz="0" izz="1"/>
    </inertial>
  </link>
  <!-- LINK DEFINITION -->
  <link name="rear_right_tibia_link">
    <visual>
      <geometry>
        <mesh filename="file:///ros2_ws/install/share/balltze_description/meshes/left_tibia_link.stl" scale="0.1 0.1 0.1"/>
      </geometry>
      <origin rpy="0.0 0.0 0.0" xyz="0.0 0.0 0.0"/>
    </visual>
    <collision>
      <geometry>
        <mesh filename="file:///ros2_ws/install/share/balltze_description/meshes/left_tibia_link_collision.stl" scale="0.1 0.1 0.1"/>
      </geometry>
      <origin rpy="0.0 0.0 0.0" xyz="0.0 0.0 0.0"/>
    </collision>
    <inertial>
      <mass value="0.00000000001"/>
      <inertia ixx="1" ixy="0" ixz="0" iyy="1" iyz="0" izz="1"/>
    </inertial>
  </link>
  <link name="rear_right_tip_link">
    <visual>
      <geometry>
        <mesh filename="file:///ros2_ws/install/share/balltze_description/meshes/left_coxa_link.stl" scale="0.1 0.1 0.1"/>
      </geometry>
      <origin rpy="0.0 0.0 0.0" xyz="0.0 0.0 0.0"/>
    </visual>
    <collision>
      <geometry>
        <mesh filename="file:///ros2_ws/install/share/balltze_description/meshes/left_coxa_link_collision.stl" scale="0.1 0.1 0.1"/>
      </geometry>
      <origin rpy="0.0 0.0 0.0" xyz="0.0 0.0 0.0"/>
    </collision>
  </link>
  <!-- JOINT DEFINITION -->
  <joint name="rear_right_body_link_to_body_link_joint" type="revolute">
    <parent link="body_link"/>
    <child link="rear_right_coxa_link"/>
    <origin rpy="0.0 0.0 0.0" xyz="-0.15 -0.075 0.0"/>
    <axis xyz="1 0 0"/>
    <limit effort="1.5" lower="2.6179938779914944" upper="-2.6179938779914944" velocity="11.938052083641214"/>
  </joint>
  <!-- JOINT DEFINITION -->
  <joint name="rear_right_coxa_link_to_coxa_link_joint" type="revolute">
    <parent link="rear_right_coxa_link"/>
    <child link="rear_right_femur_link"/>
    <origin rpy="0.0 0.0 0.0" xyz="0.0 -0.06 0.0"/>
    <axis xyz="0 1 0"/>
    <limit effort="1.5" lower="2.6179938779914944" upper="-2.6179938779914944" velocity="11.938052083641214"/>
  </joint>
  <!-- JOINT DEFINITION -->
  <joint name="rear_right_femur_link_to_femur_link_joint" type="revolute">
    <parent link="rear_right_femur_link"/>
    <child link="rear_right_tibia_link"/>
    <origin rpy="0.0 0.0 0.0" xyz="0.0 -0.0 -0.11"/>
    <axis xyz="0 1 0"/>
    <limit effort="1.5" lower="2.6179938779914944" upper="-2.6179938779914944" velocity="11.938052083641214"/>
  </joint>
  <joint name="rear_right_tibia_link_to_tip_link_joint" type="fixed">
    <parent link="rear_right_tibia_link"/>
    <child link="rear_right_tip_link"/>
    <origin rpy="0.0 0.0 0.0" xyz="0.15 -0.0 0.0"/>
  </joint>
  <ros2_control name="DynamixelSystem" type="system">
    <hardware>
      <plugin>balltze_dynamixel_system/BalltzeDynamixelSystem</plugin>
    </hardware>
    <param name="serial_port">/dev/ttyUSB1</param>
    <param name="baudrate">1000000</param>
    <param name="return_delay">50</param>
    <joint name="front_left_body_link_to_coxa_link_joint">
      <command_interface name="position"/>
      <command_interface name="velocity"/>
      <command_interface name="effort"/>
      <state_interface name="position"/>
      <state_interface name="velocity"/>
      <state_interface name="effort"/>
      <param name="id">0</param>
    </joint>
    <joint name="front_left_coxa_link_to_femur_link_joint">
      <command_interface name="position"/>
      <command_interface name="velocity"/>
      <command_interface name="effort"/>
      <state_interface name="position"/>
      <state_interface name="velocity"/>
      <state_interface name="effort"/>
      <param name="id">1</param>
    </joint>
    <joint name="front_left_femur_link_to_tibia_link_joint">
      <command_interface name="position"/>
      <command_interface name="velocity"/>
      <command_interface name="effort"/>
      <state_interface name="position"/>
      <state_interface name="velocity"/>
      <state_interface name="effort"/>
      <param name="id">2</param>
    </joint>
    <joint name="front_right_body_link_to_coxa_link_joint">
      <command_interface name="position"/>
      <command_interface name="velocity"/>
      <command_interface name="effort"/>
      <state_interface name="position"/>
      <state_interface name="velocity"/>
      <state_interface name="effort"/>
      <param name="id">3</param>
    </joint>
    <joint name="front_right_coxa_link_to_femur_link_joint">
      <command_interface name="position"/>
      <command_interface name="velocity"/>
      <command_interface name="effort"/>
      <state_interface name="position"/>
      <state_interface name="velocity"/>
      <state_interface name="effort"/>
      <param name="id">4</param>
    </joint>
    <joint name="front_right_femur_link_to_tibia_link_joint">
      <command_interface name="position"/>
      <command_interface name="velocity"/>
      <command_interface name="effort"/>
      <state_interface name="position"/>
      <state_interface name="velocity"/>
      <state_interface name="effort"/>
      <param name="id">5</param>
    </joint>
    <joint name="rear_left_body_link_to_coxa_link_joint">
      <command_interface name="position"/>
      <command_interface name="velocity"/>
      <command_interface name="effort"/>
      <state_interface name="position"/>
      <state_interface name="velocity"/>
      <state_interface name="effort"/>
      <param name="id">6</param>
    </joint>
    <joint name="rear_left_coxa_link_to_femur_link_joint">
      <command_interface name="position"/>
      <command_interface name="velocity"/>
      <command_interface name="effort"/>
      <state_interface name="position"/>
      <state_interface name="velocity"/>
      <state_interface name="effort"/>
      <param name="id">7</param>
    </joint>
    <joint name="rear_left_femur_link_to_tibia_link_joint">
      <command_interface name="position"/>
      <command_interface name="velocity"/>
      <command_interface name="effort"/>
      <state_interface name="position"/>
      <state_interface name="velocity"/>
      <state_interface name="effort"/>
      <param name="id">8</param>
    </joint>
    <joint name="rear_right_body_link_to_coxa_link_joint">
      <command_interface name="position"/>
      <command_interface name="velocity"/>
      <command_interface name="effort"/>
      <state_interface name="position"/>
      <state_interface name="velocity"/>
      <state_interface name="effort"/>
      <param name="id">9</param>
    </joint>
    <joint name="rear_right_coxa_link_to_femur_link_joint">
      <command_interface name="position"/>
      <command_interface name="velocity"/>
      <command_interface name="effort"/>
      <state_interface name="position"/>
      <state_interface name="velocity"/>
      <state_interface name="effort"/>
      <param name="id">10</param>
    </joint>
    <joint name="rear_right_femur_link_to_tibia_link_joint">
      <command_interface name="position"/>
      <command_interface name="velocity"/>
      <command_interface name="effort"/>
      <state_interface name="position"/>
      <state_interface name="velocity"/>
      <state_interface name="effort"/>
      <param name="id">11</param>
    </joint>
  </ros2_control>
</robot>
