<?xml version="1.0" ?>
<!-- =================================================================================== -->
<!-- |    This document was autogenerated by xacro from /ros2_ws/src/balltze_description/urdf/balltze.urdf.xacro | -->
<!-- |    EDITING THIS FILE BY HAND IS NOT RECOMMENDED                                 | -->
<!-- =================================================================================== -->
<robot name="balltze">
  <!-- base_link defining macro -->
  ]
  
  <link name="dummy">
    <inertial>
      <mass value="0.00000000001"/>
      <inertia ixx="1" ixy="0" ixz="0" iyy="1" iyz="0" izz="1"/>
    </inertial>
  </link>
  <link name="base_link">
    <visual>
      <geometry>
        <box size="0.5                      0.2                      0.1"/>
      </geometry>
      <origin xyz="0 0 0"/>
    </visual>
    <collision>
      <geometry>
        <box size="0.5                      0.2                      0.1"/>
      </geometry>
    </collision>
    `

      
    <inertial>
      <mass value="10.0"/>
      <inertia ixx="0.00022432" ixy="0.0" ixz="0.0" iyy="0.0041164" iyz="0.0" izz="0.00422412"/>
    </inertial>
  </link>
  <joint name="dummy_to_base_link_joint" type="fixed">
    <origin rpy="0 0 0" xyz="0 0 0"/>
    <parent link="dummy"/>
    <child link="base_link"/>
  </joint>
  <!-- LINK DEFINITION -->
  <link name="fr_coxa">
    <visual>
      <geometry>
        <box size="0.03                          0.03                          0.03"/>
      </geometry>
      <origin rpy="1.5707963267948966 0 0" xyz="0.0 0.0 -0.0"/>
    </visual>
    <collision>
      <geometry>
        <sphere radius="0.015"/>
      </geometry>
      <origin rpy="0 0 0" xyz="0.015 0 0"/>
    </collision>
    <inertial>
      <mass value="0.12131"/>
      <inertia ixx="9.165e-05" ixy="5.98e-06" ixz="-1.8e-06" iyy="3.309e-05" iyz="-1.473e-05" izz="8.256e-05"/>
    </inertial>
    <contact>
      <friction_anchor/>
      <stiffness value="30000.0"/>
      <damping value="1000.0"/>
      <spinning_friction value="0.3"/>
      <lateral_friction value="3.0"/>
    </contact>
  </link>
  <!-- LINK DEFINITION -->
  <link name="fr_femur">
    <visual>
      <geometry>
        <box size="0.16                          0.03                          0.03"/>
      </geometry>
      <origin rpy="1.5707963267948966 0 0" xyz="0.08 0.0 0.0"/>
    </visual>
    <collision>
      <geometry>
        <sphere radius="0.015"/>
      </geometry>
      <origin rpy="0 0 0" xyz="0.14500000000000002 0 0"/>
    </collision>
    <inertial>
      <mass value="0.12131"/>
      <inertia ixx="9.165e-05" ixy="5.98e-06" ixz="-1.8e-06" iyy="3.309e-05" iyz="-1.473e-05" izz="8.256e-05"/>
    </inertial>
    <contact>
      <friction_anchor/>
      <stiffness value="30000.0"/>
      <damping value="1000.0"/>
      <spinning_friction value="0.3"/>
      <lateral_friction value="3.0"/>
    </contact>
  </link>
  <!-- LINK DEFINITION -->
  <link name="fr_tibia">
    <visual>
      <geometry>
        <box size="0.16                          0.03                          0.03"/>
      </geometry>
      <origin rpy="1.5707963267948966 0 0" xyz="0.08 0.0 0.0"/>
    </visual>
    <collision>
      <geometry>
        <sphere radius="0.015"/>
      </geometry>
      <origin rpy="0 0 0" xyz="0.14500000000000002 0 0"/>
    </collision>
    <inertial>
      <mass value="0.12131"/>
      <inertia ixx="9.165e-05" ixy="5.98e-06" ixz="-1.8e-06" iyy="3.309e-05" iyz="-1.473e-05" izz="8.256e-05"/>
    </inertial>
    <contact>
      <friction_anchor/>
      <stiffness value="30000.0"/>
      <damping value="1000.0"/>
      <spinning_friction value="0.3"/>
      <lateral_friction value="3.0"/>
    </contact>
  </link>
  <!-- JOINT DEFINITION -->
  <joint name="fr_base_link_to_coxa_joint" type="revolute">
    <parent link="base_link"/>
    <origin rpy="0 0 0" xyz="0.25 -0.13 0.0"/>
    <child link="fr_coxa"/>
    <axis xyz="1 0 0"/>
    <limit effort="200" lower="-0.785398163" upper="0.785398163" velocity="5.0"/>
    <dynamics damping="0.0" friction="0.0"/>
  </joint>
  <!-- JOINT DEFINITION -->
  <joint name="fr_coxa_to_femur_joint" type="revolute">
    <parent link="fr_coxa"/>
    <origin rpy="0 1.5707963267948966 0" xyz="0.0 0.0 0.0"/>
    <child link="fr_femur"/>
    <axis xyz="0 -1 0"/>
    <limit effort="200" lower="-2.35619449" upper="1.570796327" velocity="5.0"/>
    <dynamics damping="0.0" friction="0.0"/>
  </joint>
  <!-- JOINT DEFINITION -->
  <joint name="fr_femur_to_tibia_joint" type="revolute">
    <parent link="fr_femur"/>
    <origin rpy="0 0 0" xyz="0.16 0.0 0.0"/>
    <child link="fr_tibia"/>
    <axis xyz="0 -1 0"/>
    <limit effort="200" lower="0.0" upper="3.141592654" velocity="5.0"/>
    <dynamics damping="0.0" friction="0.0"/>
  </joint>
  <!-- LINK DEFINITION -->
  <link name="fl_coxa">
    <visual>
      <geometry>
        <box size="0.03                          0.03                          0.03"/>
      </geometry>
      <origin rpy="1.5707963267948966 0 0" xyz="0.0 0.0 -0.0"/>
    </visual>
    <collision>
      <geometry>
        <sphere radius="0.015"/>
      </geometry>
      <origin rpy="0 0 0" xyz="0.015 0 0"/>
    </collision>
    <inertial>
      <mass value="0.12131"/>
      <inertia ixx="9.165e-05" ixy="5.98e-06" ixz="-1.8e-06" iyy="3.309e-05" iyz="-1.473e-05" izz="8.256e-05"/>
    </inertial>
    <contact>
      <friction_anchor/>
      <stiffness value="30000.0"/>
      <damping value="1000.0"/>
      <spinning_friction value="0.3"/>
      <lateral_friction value="3.0"/>
    </contact>
  </link>
  <!-- LINK DEFINITION -->
  <link name="fl_femur">
    <visual>
      <geometry>
        <box size="0.16                          0.03                          0.03"/>
      </geometry>
      <origin rpy="1.5707963267948966 0 0" xyz="0.08 0.0 0.0"/>
    </visual>
    <collision>
      <geometry>
        <sphere radius="0.015"/>
      </geometry>
      <origin rpy="0 0 0" xyz="0.14500000000000002 0 0"/>
    </collision>
    <inertial>
      <mass value="0.12131"/>
      <inertia ixx="9.165e-05" ixy="5.98e-06" ixz="-1.8e-06" iyy="3.309e-05" iyz="-1.473e-05" izz="8.256e-05"/>
    </inertial>
    <contact>
      <friction_anchor/>
      <stiffness value="30000.0"/>
      <damping value="1000.0"/>
      <spinning_friction value="0.3"/>
      <lateral_friction value="3.0"/>
    </contact>
  </link>
  <!-- LINK DEFINITION -->
  <link name="fl_tibia">
    <visual>
      <geometry>
        <box size="0.16                          0.03                          0.03"/>
      </geometry>
      <origin rpy="1.5707963267948966 0 0" xyz="0.08 0.0 0.0"/>
    </visual>
    <collision>
      <geometry>
        <sphere radius="0.015"/>
      </geometry>
      <origin rpy="0 0 0" xyz="0.14500000000000002 0 0"/>
    </collision>
    <inertial>
      <mass value="0.12131"/>
      <inertia ixx="9.165e-05" ixy="5.98e-06" ixz="-1.8e-06" iyy="3.309e-05" iyz="-1.473e-05" izz="8.256e-05"/>
    </inertial>
    <contact>
      <friction_anchor/>
      <stiffness value="30000.0"/>
      <damping value="1000.0"/>
      <spinning_friction value="0.3"/>
      <lateral_friction value="3.0"/>
    </contact>
  </link>
  <!-- JOINT DEFINITION -->
  <joint name="fl_base_link_to_coxa_joint" type="revolute">
    <parent link="base_link"/>
    <origin rpy="0 0 0" xyz="0.25 0.13 0.0"/>
    <child link="fl_coxa"/>
    <axis xyz="1 0 0"/>
    <limit effort="200" lower="-0.785398163" upper="0.785398163" velocity="5.0"/>
    <dynamics damping="0.0" friction="0.0"/>
  </joint>
  <!-- JOINT DEFINITION -->
  <joint name="fl_coxa_to_femur_joint" type="revolute">
    <parent link="fl_coxa"/>
    <origin rpy="0 1.5707963267948966 0" xyz="0.0 0.0 0.0"/>
    <child link="fl_femur"/>
    <axis xyz="0 -1 0"/>
    <limit effort="200" lower="-2.35619449" upper="1.570796327" velocity="5.0"/>
    <dynamics damping="0.0" friction="0.0"/>
  </joint>
  <!-- JOINT DEFINITION -->
  <joint name="fl_femur_to_tibia_joint" type="revolute">
    <parent link="fl_femur"/>
    <origin rpy="0 0 0" xyz="0.16 0.0 0.0"/>
    <child link="fl_tibia"/>
    <axis xyz="0 -1 0"/>
    <limit effort="200" lower="0.0" upper="3.141592654" velocity="5.0"/>
    <dynamics damping="0.0" friction="0.0"/>
  </joint>
  <!-- LINK DEFINITION -->
  <link name="rr_coxa">
    <visual>
      <geometry>
        <box size="0.03                          0.03                          0.03"/>
      </geometry>
      <origin rpy="1.5707963267948966 0 0" xyz="0.0 0.0 -0.0"/>
    </visual>
    <collision>
      <geometry>
        <sphere radius="0.015"/>
      </geometry>
      <origin rpy="0 0 0" xyz="0.015 0 0"/>
    </collision>
    <inertial>
      <mass value="0.12131"/>
      <inertia ixx="9.165e-05" ixy="5.98e-06" ixz="-1.8e-06" iyy="3.309e-05" iyz="-1.473e-05" izz="8.256e-05"/>
    </inertial>
    <contact>
      <friction_anchor/>
      <stiffness value="30000.0"/>
      <damping value="1000.0"/>
      <spinning_friction value="0.3"/>
      <lateral_friction value="3.0"/>
    </contact>
  </link>
  <!-- LINK DEFINITION -->
  <link name="rr_femur">
    <visual>
      <geometry>
        <box size="0.16                          0.03                          0.03"/>
      </geometry>
      <origin rpy="1.5707963267948966 0 0" xyz="0.08 0.0 0.0"/>
    </visual>
    <collision>
      <geometry>
        <sphere radius="0.015"/>
      </geometry>
      <origin rpy="0 0 0" xyz="0.14500000000000002 0 0"/>
    </collision>
    <inertial>
      <mass value="0.12131"/>
      <inertia ixx="9.165e-05" ixy="5.98e-06" ixz="-1.8e-06" iyy="3.309e-05" iyz="-1.473e-05" izz="8.256e-05"/>
    </inertial>
    <contact>
      <friction_anchor/>
      <stiffness value="30000.0"/>
      <damping value="1000.0"/>
      <spinning_friction value="0.3"/>
      <lateral_friction value="3.0"/>
    </contact>
  </link>
  <!-- LINK DEFINITION -->
  <link name="rr_tibia">
    <visual>
      <geometry>
        <box size="0.16                          0.03                          0.03"/>
      </geometry>
      <origin rpy="1.5707963267948966 0 0" xyz="0.08 0.0 0.0"/>
    </visual>
    <collision>
      <geometry>
        <sphere radius="0.015"/>
      </geometry>
      <origin rpy="0 0 0" xyz="0.14500000000000002 0 0"/>
    </collision>
    <inertial>
      <mass value="0.12131"/>
      <inertia ixx="9.165e-05" ixy="5.98e-06" ixz="-1.8e-06" iyy="3.309e-05" iyz="-1.473e-05" izz="8.256e-05"/>
    </inertial>
    <contact>
      <friction_anchor/>
      <stiffness value="30000.0"/>
      <damping value="1000.0"/>
      <spinning_friction value="0.3"/>
      <lateral_friction value="3.0"/>
    </contact>
  </link>
  <!-- JOINT DEFINITION -->
  <joint name="rr_base_link_to_coxa_joint" type="revolute">
    <parent link="base_link"/>
    <origin rpy="0 0 0" xyz="-0.25 -0.13 0.0"/>
    <child link="rr_coxa"/>
    <axis xyz="1 0 0"/>
    <limit effort="200" lower="-0.785398163" upper="0.785398163" velocity="5.0"/>
    <dynamics damping="0.0" friction="0.0"/>
  </joint>
  <!-- JOINT DEFINITION -->
  <joint name="rr_coxa_to_femur_joint" type="revolute">
    <parent link="rr_coxa"/>
    <origin rpy="0 1.5707963267948966 0" xyz="0.0 0.0 0.0"/>
    <child link="rr_femur"/>
    <axis xyz="0 -1 0"/>
    <limit effort="200" lower="-2.35619449" upper="1.570796327" velocity="5.0"/>
    <dynamics damping="0.0" friction="0.0"/>
  </joint>
  <!-- JOINT DEFINITION -->
  <joint name="rr_femur_to_tibia_joint" type="revolute">
    <parent link="rr_femur"/>
    <origin rpy="0 0 0" xyz="0.16 0.0 0.0"/>
    <child link="rr_tibia"/>
    <axis xyz="0 -1 0"/>
    <limit effort="200" lower="0.0" upper="3.141592654" velocity="5.0"/>
    <dynamics damping="0.0" friction="0.0"/>
  </joint>
  <!-- LINK DEFINITION -->
  <link name="rl_coxa">
    <visual>
      <geometry>
        <box size="0.03                          0.03                          0.03"/>
      </geometry>
      <origin rpy="1.5707963267948966 0 0" xyz="0.0 0.0 -0.0"/>
    </visual>
    <collision>
      <geometry>
        <sphere radius="0.015"/>
      </geometry>
      <origin rpy="0 0 0" xyz="0.015 0 0"/>
    </collision>
    <inertial>
      <mass value="0.12131"/>
      <inertia ixx="9.165e-05" ixy="5.98e-06" ixz="-1.8e-06" iyy="3.309e-05" iyz="-1.473e-05" izz="8.256e-05"/>
    </inertial>
    <contact>
      <friction_anchor/>
      <stiffness value="30000.0"/>
      <damping value="1000.0"/>
      <spinning_friction value="0.3"/>
      <lateral_friction value="3.0"/>
    </contact>
  </link>
  <!-- LINK DEFINITION -->
  <link name="rl_femur">
    <visual>
      <geometry>
        <box size="0.16                          0.03                          0.03"/>
      </geometry>
      <origin rpy="1.5707963267948966 0 0" xyz="0.08 0.0 0.0"/>
    </visual>
    <collision>
      <geometry>
        <sphere radius="0.015"/>
      </geometry>
      <origin rpy="0 0 0" xyz="0.14500000000000002 0 0"/>
    </collision>
    <inertial>
      <mass value="0.12131"/>
      <inertia ixx="9.165e-05" ixy="5.98e-06" ixz="-1.8e-06" iyy="3.309e-05" iyz="-1.473e-05" izz="8.256e-05"/>
    </inertial>
    <contact>
      <friction_anchor/>
      <stiffness value="30000.0"/>
      <damping value="1000.0"/>
      <spinning_friction value="0.3"/>
      <lateral_friction value="3.0"/>
    </contact>
  </link>
  <!-- LINK DEFINITION -->
  <link name="rl_tibia">
    <visual>
      <geometry>
        <box size="0.16                          0.03                          0.03"/>
      </geometry>
      <origin rpy="1.5707963267948966 0 0" xyz="0.08 0.0 0.0"/>
    </visual>
    <collision>
      <geometry>
        <sphere radius="0.015"/>
      </geometry>
      <origin rpy="0 0 0" xyz="0.14500000000000002 0 0"/>
    </collision>
    <inertial>
      <mass value="0.12131"/>
      <inertia ixx="9.165e-05" ixy="5.98e-06" ixz="-1.8e-06" iyy="3.309e-05" iyz="-1.473e-05" izz="8.256e-05"/>
    </inertial>
    <contact>
      <friction_anchor/>
      <stiffness value="30000.0"/>
      <damping value="1000.0"/>
      <spinning_friction value="0.3"/>
      <lateral_friction value="3.0"/>
    </contact>
  </link>
  <!-- JOINT DEFINITION -->
  <joint name="rl_base_link_to_coxa_joint" type="revolute">
    <parent link="base_link"/>
    <origin rpy="0 0 0" xyz="-0.25 0.13 0.0"/>
    <child link="rl_coxa"/>
    <axis xyz="1 0 0"/>
    <limit effort="200" lower="-0.785398163" upper="0.785398163" velocity="5.0"/>
    <dynamics damping="0.0" friction="0.0"/>
  </joint>
  <!-- JOINT DEFINITION -->
  <joint name="rl_coxa_to_femur_joint" type="revolute">
    <parent link="rl_coxa"/>
    <origin rpy="0 1.5707963267948966 0" xyz="0.0 0.0 0.0"/>
    <child link="rl_femur"/>
    <axis xyz="0 -1 0"/>
    <limit effort="200" lower="-2.35619449" upper="1.570796327" velocity="5.0"/>
    <dynamics damping="0.0" friction="0.0"/>
  </joint>
  <!-- JOINT DEFINITION -->
  <joint name="rl_femur_to_tibia_joint" type="revolute">
    <parent link="rl_femur"/>
    <origin rpy="0 0 0" xyz="0.16 0.0 0.0"/>
    <child link="rl_tibia"/>
    <axis xyz="0 -1 0"/>
    <limit effort="200" lower="0.0" upper="3.141592654" velocity="5.0"/>
    <dynamics damping="0.0" friction="0.0"/>
  </joint>
</robot>
